2021-12-08 17:23:31,615 ERROR: Exception on /reset_password_request [POST] [in /home/pontotel/Documents/Honorato/Flask/microblog/microblog/lib/python3.8/site-packages/flask/app.py:1457]
Traceback (most recent call last):
  File "/home/pontotel/Documents/Honorato/Flask/microblog/microblog/lib/python3.8/site-packages/flask_mail.py", line 492, in send
    message.send(connection)
  File "/home/pontotel/Documents/Honorato/Flask/microblog/microblog/lib/python3.8/site-packages/flask_mail.py", line 427, in send
    connection.send(self)
  File "/home/pontotel/Documents/Honorato/Flask/microblog/microblog/lib/python3.8/site-packages/flask_mail.py", line 188, in send
    self.host.sendmail(sanitize_address(envelope_from or message.sender),
  File "/usr/lib/python3.8/smtplib.py", line 865, in sendmail
    self.ehlo_or_helo_if_needed()
  File "/usr/lib/python3.8/smtplib.py", line 604, in ehlo_or_helo_if_needed
    if not (200 <= self.ehlo()[0] <= 299):
  File "/usr/lib/python3.8/smtplib.py", line 444, in ehlo
    self.putcmd(self.ehlo_msg, name or self.local_hostname)
  File "/usr/lib/python3.8/smtplib.py", line 371, in putcmd
    self.send(str)
  File "/usr/lib/python3.8/smtplib.py", line 363, in send
    raise SMTPServerDisconnected('please run connect() first')
smtplib.SMTPServerDisconnected: please run connect() first

During handling of the above exception, another exception occurred:

Traceback (most recent call last):
  File "/home/pontotel/Documents/Honorato/Flask/microblog/microblog/lib/python3.8/site-packages/flask/app.py", line 2073, in wsgi_app
    response = self.full_dispatch_request()
  File "/home/pontotel/Documents/Honorato/Flask/microblog/microblog/lib/python3.8/site-packages/flask/app.py", line 1518, in full_dispatch_request
    rv = self.handle_user_exception(e)
  File "/home/pontotel/Documents/Honorato/Flask/microblog/microblog/lib/python3.8/site-packages/flask/app.py", line 1516, in full_dispatch_request
    rv = self.dispatch_request()
  File "/home/pontotel/Documents/Honorato/Flask/microblog/microblog/lib/python3.8/site-packages/flask/app.py", line 1502, in dispatch_request
    return self.ensure_sync(self.view_functions[rule.endpoint])(**req.view_args)
  File "/home/pontotel/Documents/Honorato/Flask/microblog/app/routes.py", line 152, in reset_password_request
    send_password_reset_email(user)
  File "/home/pontotel/Documents/Honorato/Flask/microblog/app/email.py", line 13, in send_password_reset_email
    send_email('[Microblog] Reset Your Password',
  File "/home/pontotel/Documents/Honorato/Flask/microblog/app/email.py", line 9, in send_email
    mail.send(msg)
  File "/home/pontotel/Documents/Honorato/Flask/microblog/microblog/lib/python3.8/site-packages/flask_mail.py", line 492, in send
    message.send(connection)
  File "/home/pontotel/Documents/Honorato/Flask/microblog/microblog/lib/python3.8/site-packages/flask_mail.py", line 152, in __exit__
    self.host.quit()
  File "/usr/lib/python3.8/smtplib.py", line 997, in quit
    res = self.docmd("quit")
  File "/usr/lib/python3.8/smtplib.py", line 424, in docmd
    self.putcmd(cmd, args)
  File "/usr/lib/python3.8/smtplib.py", line 371, in putcmd
    self.send(str)
  File "/usr/lib/python3.8/smtplib.py", line 363, in send
    raise SMTPServerDisconnected('please run connect() first')
smtplib.SMTPServerDisconnected: please run connect() first
2021-12-08 17:30:51,775 INFO: Microblog statup [in /home/pontotel/Documents/Honorato/Flask/microblog/app/__init__.py:46]
2021-12-08 19:41:23,435 INFO: Microblog statup [in /home/pontotel/Documents/Honorato/Flask/microblog/app/__init__.py:46]
2021-12-08 19:52:21,269 INFO: Microblog startup [in /home/pontotel/Documents/Honorato/Flask/microblog/app/__init__.py:84]
